Workbook

Sheet 明细
A1: 发货人 SHIPPER: | F1: 经营单位
F2: 中文名： | G2: 上海福洺电子商务有限公司
A3: 上海福洺电子商务有限公司 | F3: 英文名：
F4: 营业执照号 | G4: 91310120MABY7LT67T
F5: 申报单位
A6: 收货人 CONSGINEE： | F6: 中文名： | G6: 上海福洺电子商务有限公司
A7: Amazon.com Services, Inc. | F7: 10位编码
F8: 其他
F9: 发票号 | G9: HY26011821-1
F10: 发票上显示成交方式 | G10: FOB SHANGHAI
F11: 运输方式 | G11: BY SEA
A12: 通知人 Notify： | F12: 包装种类 | G12: CARTONS
A13: =A7 -> Amazon.com Services, Inc. | F13: 出口口岸 | G13: SHANGHAI
F14: 贸易国（地区） | G14: 美国
F15: 运抵国（地区） | G15: 美国
F16: 指运港
A17: 唛头： | F17: 成交方式 | G17: FOB
F18: 境内货源地
F19: 运费
F20: 保费
F21: 货币单位 | G21: USD | H21: 美元
F22: 日期 | G22: 46048
A25: 序号 | B25: 英文名 | C25: 中文名 | D25: HS | E25: G.W KGS | F25: N.W KGS | G25: 单价 USD | H25: 金额 FOB | I25: 数量 | J25: 中文单位 | K25: (英文单位) | L25: 箱数 | M25: 包装单位 | N25: CBM | O25: 申报要素 | P25: 货源地
A26: 1 | B26: SCREWS | C26: 螺钉 | D26: 7318159090 | E26: 15.6 | F26: =E26-L26 -> 14.6 | G26: 6.22 | H26: =G26*I26 -> 99.52 | I26: 16 | J26: 套 | K26: PCS | L26: 1 | M26: 箱 | N26: 0.017024 | O26: 0|0|不锈钢|460-750MPA|无品牌|无型号|4.85MM | P26: 上海奉贤 | Q26: YS323
A27: 2 | B27: SCREWS | C27: 螺钉 | D27: 7318159090 | E27: 15.3 | F27: =E27-L27 -> 14.3 | G27: 9.38 | H27: =G27*I27 -> 112.56 | I27: 12 | J27: 套 | K27: PCS | L27: 1 | M27: 箱 | N27: 0.017024 | O27: 0|0|不锈钢|460-750MPA|无品牌|无型号|4.85MM | P27: 上海奉贤 | Q27: YS325
A28: 3 | B28: SCREWS | C28: 螺钉 | D28: 7318159090 | E28: 17.8 | F28: =E28-L28 -> 15.8 | G28: 10.68 | H28: =G28*I28 -> 128.16 | I28: 12 | J28: 套 | K28: PCS | L28: 2 | M28: 箱 | N28: 0.02088 | O28: 0|0|不锈钢|460-750MPA|无品牌|无型号|4.85MM | P28: 上海奉贤 | Q28: YS327
A29: 4 | B29: SCREWS | C29: 螺钉 | D29: 7318159090 | E29: 15.7 | F29: =E29-L29 -> 13.7 | G29: 3.49 | H29: =G29*I29 -> 125.64 | I29: 36 | J29: 套 | K29: PCS | L29: 2 | M29: 箱 | N29: 0.02184 | O29: 0|0|不锈钢|460-750MPA|无品牌|无型号|4.85MM | P29: 上海奉贤 | Q29: YS328
A30: 5 | B30: SCREWS | C30: 螺钉 | D30: 7318159090 | E30: 35.4 | F30: =E30-L30 -> 32.4 | G30: 7.52 | H30: =G30*I30 -> 270.72 | I30: 36 | J30: 套 | K30: PCS | L30: 3 | M30: 箱 | N30: 0.051072 | O30: 0|0|不锈钢|460-750MPA|无品牌|无型号|4.85MM | P30: 上海奉贤 | Q30: YS329
A31: 6 | B31: SCREWS | C31: 螺钉 | D31: 7318159090 | E31: 21.2 | F31: =E31-L31 -> 19.2 | G31: 13.74 | H31: =G31*I31 -> 109.92 | I31: 8 | J31: 套 | K31: PCS | L31: 2 | M31: 箱 | N31: 0.04786875 | O31: 0|0|不锈钢|460-750MPA|无品牌|无型号|4.85MM | P31: 上海奉贤 | Q31: YS145
A32: 7 | B32: SCREWS | C32: 螺钉 | D32: 7318159090 | E32: 14.5 | F32: =E32-L32 -> 13.5 | G32: 7.99 | H32: =G32*I32 -> 95.88 | I32: 12 | J32: 套 | K32: PCS | L32: 1 | M32: 箱 | N32: 0.014616 | O32: 0|0|不锈钢|460-750MPA|无品牌|无型号|4.85MM | P32: 上海奉贤 | Q32: YS161
A33: 8 | B33: Railing bracket | C33: 栏杆支架 | D33: 7326909000 | E33: 17.31 | F33: =E33-L33 -> 14.31 | G33: 30.09 | H33: =G33*I33 -> 90.27 | I33: 3 | J33: 套 | K33: PCS | L33: 3 | M33: 箱 | N33: 0.014322 | O33: 0|0|非工业用|铁|锻造 | P33: 江苏盐城 | Q33: YS382
A34: 9 | B34: Railing bracket | C34: 栏杆支架 | D34: 7326909000 | E34: 12.7 | F34: =E34-L34 -> 11.7 | G34: 5.01 | H34: =G34*I34 -> 60.12 | I34: 12 | J34: 套 | K34: PCS | L34: 1 | M34: 箱 | N34: 0.019227 | O34: 0|0|非工业用|铁|锻造 | P34: 江苏盐城 | Q34: YS125
A35: 10 | B35: Railing bracket | C35: 栏杆支架 | D35: 7326909000 | E35: 12.25 | F35: =E35-L35 -> 11.25 | G35: 10.03 | H35: =G35*I35 -> 60.18 | I35: 6 | J35: 套 | K35: PCS | L35: 1 | M35: 箱 | N35: 0.019227 | O35: 0|0|非工业用|铁|锻造 | P35: 江苏盐城 | Q35: YS124
A36: 11 | B36: Railing bracket | C36: 栏杆支架 | D36: 7326909000 | E36: 15.44 | F36: =E36-L36 -> 11.44 | G36: 20.06 | H36: =G36*I36 -> 80.24 | I36: 4 | J36: 套 | K36: PCS | L36: 4 | M36: 箱 | N36: 0.013608 | O36: 0|0|非工业用|铁|锻造 | P36: 江苏盐城 | Q36: YS381
A37: 12 | B37: SCREWS | C37: 螺钉 | D37: 7318159090 | E37: 29.6 | F37: =E37-L37 -> 27.6 | G37: 11.11 | H37: =G37*I37 -> 133.32 | I37: 12 | J37: 套 | K37: PCS | L37: 2 | M37: 箱 | N37: 0.07106 | O37: 0|0|铁|460-750MPA|无品牌|无型号|4.85MM | P37: 河北邯郸 | Q37: YS356
... A75: 50 | B75: SCREWS | C75: 螺钉 | D75: 7318159090 | E75: 99 | F75: =E75-L75 -> 93 | G75: 4.29 | H75: =G75*I75 -> 411.84 | I75: 96 | J75: 套 | K75: PCS | L75: 6 | M75: 箱 | N75: 0.102144 | O75: 0|0|铁|460-750MPA|无品牌|无型号|4.85MM | P75: 上海奉贤 | Q75: YS50
E76: =SUM(E26:E75) -> 2228.76 | F76: =SUM(F26:F75) -> 1958.76 | H76: =SUM(H26:H75) -> 9282.33 | I76: =SUM(I26:I75) -> 1071 | K76: PCS | L76: =SUM(L26:L75) -> 270 | M76: 箱 | N76: =SUM(N26:N75) -> 3.892832
A77: http://www.hscode.net/IntegrateQueries/QueryYS/ | D77: 申报要素查询网站

Sheet 发票
A1: =明细!G2 -> 上海福洺电子商务有限公司
A2: =明细!G3 -> 0
A3: COMMERCIAL INVOICE
A5: =明细!G10 -> FOB SHANGHAI | F5: Invoice No: | G5: =明细!G9 -> HY26011821-1
A6: CONSIGNEE: | B6: =明细!A7 -> Amazon.com Services, Inc. | F6: DATE: | G6: =明细!G22 -> 46048
A7: FROM: | B7: =明细!G13 -> SHANGHAI | F7: TO: | G7: =明细!G15 -> 美国
A8: DESCRIPTION OF GOODS | D8: QUANTITY | F8: UNIT PRICE（USD） | G8: AMOUNT（FOB）
A9: =明细!B26 -> SCREWS | B9: =明细!C26 -> 螺钉 | D9: =明细!I26 -> 16 | E9: =明细!K26 -> PCS | F9: =明细!G26 -> 6.22 | G9: =明细!H26 -> 99.52 | H9: =明细!Q26 -> YS323
A10: =明细!B27 -> SCREWS | B10: =明细!C27 -> 螺钉 | D10: =明细!I27 -> 12 | E10: =明细!K27 -> PCS | F10: =明细!G27 -> 9.38 | G10: =明细!H27 -> 112.56 | H10: =明细!Q27 -> YS325
A11: =明细!B28 -> SCREWS | B11: =明细!C28 -> 螺钉 | D11: =明细!I28 -> 12 | E11: =明细!K28 -> PCS | F11: =明细!G28 -> 10.68 | G11: =明细!H28 -> 128.16 | H11: =明细!Q28 -> YS327
A12: =明细!B29 -> SCREWS | B12: =明细!C29 -> 螺钉 | D12: =明细!I29 -> 36 | E12: =明细!K29 -> PCS | F12: =明细!G29 -> 3.49 | G12: =明细!H29 -> 125.64 | H12: =明细!Q29 -> YS328
A13: =明细!B30 -> SCREWS | B13: =明细!C30 -> 螺钉 | D13: =明细!I30 -> 36 | E13: =明细!K30 -> PCS | F13: =明细!G30 -> 7.52 | G13: =明细!H30 -> 270.72 | H13: =明细!Q30 -> YS329
A14: =明细!B31 -> SCREWS | B14: =明细!C31 -> 螺钉 | D14: =明细!I31 -> 8 | E14: =明细!K31 -> PCS | F14: =明细!G31 -> 13.74 | G14: =明细!H31 -> 109.92 | H14: =明细!Q31 -> YS145
A15: =明细!B32 -> SCREWS | B15: =明细!C32 -> 螺钉 | D15: =明细!I32 -> 12 | E15: =明细!K32 -> PCS | F15: =明细!G32 -> 7.99 | G15: =明细!H32 -> 95.88 | H15: =明细!Q32 -> YS161
A16: =明细!B33 -> Railing bracket | B16: =明细!C33 -> 栏杆支架 | D16: =明细!I33 -> 3 | E16: =明细!K33 -> PCS | F16: =明细!G33 -> 30.09 | G16: =明细!H33 -> 90.27 | H16: =明细!Q33 -> YS382
A17: =明细!B34 -> Railing bracket | B17: =明细!C34 -> 栏杆支架 | D17: =明细!I34 -> 12 | E17: =明细!K34 -> PCS | F17: =明细!G34 -> 5.01 | G17: =明细!H34 -> 60.12 | H17: =明细!Q34 -> YS125
A18: =明细!B35 -> Railing bracket | B18: =明细!C35 -> 栏杆支架 | D18: =明细!I35 -> 6 | E18: =明细!K35 -> PCS | F18: =明细!G35 -> 10.03 | G18: =明细!H35 -> 60.18 | H18: =明细!Q35 -> YS124
A19: =明细!B36 -> Railing bracket | B19: =明细!C36 -> 栏杆支架 | D19: =明细!I36 -> 4 | E19: =明细!K36 -> PCS | F19: =明细!G36 -> 20.06 | G19: =明细!H36 -> 80.24 | H19: =明细!Q36 -> YS381
A20: =明细!B37 -> SCREWS | B20: =明细!C37 -> 螺钉 | D20: =明细!I37 -> 12 | E20: =明细!K37 -> PCS | F20: =明细!G37 -> 11.11 | G20: =明细!H37 -> 133.32 | H20: =明细!Q37 -> YS356
... A58: =明细!B75 -> SCREWS | B58: =明细!C75 -> 螺钉 | D58: =明细!I75 -> 96 | E58: =明细!K75 -> PCS | F58: =明细!G75 -> 4.29 | G58: =明细!H75 -> 411.84 | H58: =明细!Q75 -> YS50
A59: TOTAL: | D59: =SUM(D9:D58) -> 1071 | G59: =SUM(G9:G58) -> 9282.33

Sheet 外销合同
G1: 合同号码: Contract No: | H1: =明细!G9 -> HY26011821-1
B2: 订 购 合 同
G3: 日 期 Date: | H3: =明细!G22 -> 46048
B4: PURCHASE CONTRACT
G5: 签订地点 Signed At: | H5: =明细!G18 -> 0
A7: 买 方 The buyers: | B7: =明细!A7 -> Amazon.com Services, Inc. | G7: 电 话 Tel:
A9: 地 址 Address: | B9: =明细!A8 -> 0 | G9: 传 真 Fax:
A11: 卖 方 The sellers: | B11: =明细!A2 -> 0 | G11: 电 话 Tel:
A13: 地址 Address: | B13: =明细!A3 -> 上海福洺电子商务有限公司 | G13: 传 真 Fax:
A15: 兹经买卖双方同意由买方购进下列货物，并按下列条款签订本合同：
A16: This purchase contract is made by and between the Sellers and the Buyers’ whereby the Sellers agree to sell and the Buyers agree to buy the under-mentioned goods according to the terms and condictions stipulated below:
A18: 商品名称，规格及包装 | E18: 单位 | F18: 数量 | G18: 成交方式 | H18: 金额
A19: Name of Commodity ,Specification & Packing | E19: Unit | F19: Quantity | G19: FOB | H19: Value
A20: =明细!C26 -> 螺钉 | E20: =明细!K26 -> PCS | F20: =明细!I26 -> 16 | G20: =明细!G26 -> 6.22 | H20: =明细!H26 -> 99.52 | I20: =明细!Q26 -> YS323
A21: =明细!C27 -> 螺钉 | E21: =明细!K27 -> PCS | F21: =明细!I27 -> 12 | G21: =明细!G27 -> 9.38 | H21: =明细!H27 -> 112.56 | I21: =明细!Q27 -> YS325
A22: =明细!C28 -> 螺钉 | E22: =明细!K28 -> PCS | F22: =明细!I28 -> 12 | G22: =明细!G28 -> 10.68 | H22: =明细!H28 -> 128.16 | I22: =明细!Q28 -> YS327
A23: =明细!C29 -> 螺钉 | E23: =明细!K29 -> PCS | F23: =明细!I29 -> 36 | G23: =明细!G29 -> 3.49 | H23: =明细!H29 -> 125.64 | I23: =明细!Q29 -> YS328
A24: =明细!C30 -> 螺钉 | E24: =明细!K30 -> PCS | F24: =明细!I30 -> 36 | G24: =明细!G30 -> 7.52 | H24: =明细!H30 -> 270.72 | I24: =明细!Q30 -> YS329
A25: =明细!C31 -> 螺钉 | E25: =明细!K31 -> PCS | F25: =明细!I31 -> 8 | G25: =明细!G31 -> 13.74 | H25: =明细!H31 -> 109.92 | I25: =明细!Q31 -> YS145
A26: =明细!C32 -> 螺钉 | E26: =明细!K32 -> PCS | F26: =明细!I32 -> 12 | G26: =明细!G32 -> 7.99 | H26: =明细!H32 -> 95.88 | I26: =明细!Q32 -> YS161
A27: =明细!C33 -> 栏杆支架 | E27: =明细!K33 -> PCS | F27: =明细!I33 -> 3 | G27: =明细!G33 -> 30.09 | H27: =明细!H33 -> 90.27 | I27: =明细!Q33 -> YS382
A28: =明细!C34 -> 栏杆支架 | E28: =明细!K34 -> PCS | F28: =明细!I34 -> 12 | G28: =明细!G34 -> 5.01 | H28: =明细!H34 -> 60.12 | I28: =明细!Q34 -> YS125
A29: =明细!C35 -> 栏杆支架 | E29: =明细!K35 -> PCS | F29: =明细!I35 -> 6 | G29: =明细!G35 -> 10.03 | H29: =明细!H35 -> 60.18 | I29: =明细!Q35 -> YS124
A30: =明细!C36 -> 栏杆支架 | E30: =明细!K36 -> PCS | F30: =明细!I36 -> 4 | G30: =明细!G36 -> 20.06 | H30: =明细!H36 -> 80.24 | I30: =明细!Q36 -> YS381
A31: =明细!C37 -> 螺钉 | E31: =明细!K37 -> PCS | F31: =明细!I37 -> 12 | G31: =明细!G37 -> 11.11 | H31: =明细!H37 -> 133.32 | I31: =明细!Q37 -> YS356
... A69: =明细!C75 -> 螺钉 | E69: =明细!K75 -> PCS | F69: =明细!I75 -> 96 | G69: =明细!G75 -> 4.29 | H69: =明细!H75 -> 411.84 | I69: =明细!Q75 -> YS50
G73: Total: | H73: =SUM(H20:H72) -> 9282.33
A74: 总值(大写) | B74: 美元 | C74: =SUBSTITUTE(SUBSTITUTE(SUBSTITUTE(NUMBERSTRING(INT(H73),2)&"圆"&TEXT(MOD(H73,1)*100,"[dbnum2]0角0分"),"零角零分","整"),"零角","零"),"零分","") -> 玖仟贰佰捌拾贰圆叁角叁分
A75: Total Value: | B75: Say total dollars
A76: 2.装运口岸: Port of shipment: | C76: =明细!G13 -> SHANGHAI | E76: 3.目的口岸: Port of Destination: | G76: =明细!G14 -> 美国
A78: 4.装运期限: Time of Shipment: | E78: 5.装运标志: Shipping Mark:
A80: 6.付款条款: Terms of Payment:
A82: □ 买方在收到货物后 天内,以信汇方式将货款汇付卖方.
A83: After receipt of the goods ,the Buyers shall pay the total value of the invoice to the Sellers by mail transfer within days.
A84: 买方在收到货物后60 天内, 以电汇方式将货款汇付卖方.
A85: After receipt of the goods, the Buyers shall pay the total value of the invoice to the Sellers by telegraphic transfer within 60 days.
A86: □ 买方应不迟于约定装船期前 天开立不可撤销的信用证,凭买方即期跟单汇票议付,议付有效期应延至装运期后 天在到期
A87: By irrevocable Letter of Credit available by the Sellers’ documentary draft at sight, to be opened not less than days before the
A88: contracted date of shipment and to remain valid for negotiation in until the th day after the time of shipment.
A89: 7.生产国别及制造厂商:
...

Sheet 箱单
A1: =明细!G2 -> 上海福洺电子商务有限公司
A2: =明细!G3 -> 0
A3: PACKING LIST
A5: TERMS OF PAYMENT:T/T | E5: Invoice No: | F5: =明细!G9 -> HY26011821-1
A6: CONSIGNEE: | B6: =明细!A7 -> Amazon.com Services, Inc. | E6: DATE: | F6: =明细!G22 -> 46048
A7: FROM: | B7: =明细!G13 -> SHANGHAI | E7: TO: | F7: =明细!G15 -> 美国
A8: DESCRIPTION OF GOODS | C8: Packages（PLT） | D8: Gross Wt.(KGS) | E8: Net Wt.(KGS) | F8: Measurement(M3)
A9: =明细!B26 -> SCREWS | B9: =明细!C26 -> 螺钉 | C9: =明细!L26 -> 1 | D9: =明细!E26 -> 15.6 | E9: =明细!F26 -> 14.6 | F9: =明细!N26 -> 0.017024 | G9: =明细!Q26 -> YS323
A10: =明细!B27 -> SCREWS | B10: =明细!C27 -> 螺钉 | C10: =明细!L27 -> 1 | D10: =明细!E27 -> 15.3 | E10: =明细!F27 -> 14.3 | F10: =明细!N27 -> 0.017024 | G10: =明细!Q27 -> YS325
A11: =明细!B28 -> SCREWS | B11: =明细!C28 -> 螺钉 | C11: =明细!L28 -> 2 | D11: =明细!E28 -> 17.8 | E11: =明细!F28 -> 15.8 | F11: =明细!N28 -> 0.02088 | G11: =明细!Q28 -> YS327
A12: =明细!B29 -> SCREWS | B12: =明细!C29 -> 螺钉 | C12: =明细!L29 -> 2 | D12: =明细!E29 -> 15.7 | E12: =明细!F29 -> 13.7 | F12: =明细!N29 -> 0.02184 | G12: =明细!Q29 -> YS328
A13: =明细!B30 -> SCREWS | B13: =明细!C30 -> 螺钉 | C13: =明细!L30 -> 3 | D13: =明细!E30 -> 35.4 | E13: =明细!F30 -> 32.4 | F13: =明细!N30 -> 0.051072 | G13: =明细!Q30 -> YS329
A14: =明细!B31 -> SCREWS | B14: =明细!C31 -> 螺钉 | C14: =明细!L31 -> 2 | D14: =明细!E31 -> 21.2 | E14: =明细!F31 -> 19.2 | F14: =明细!N31 -> 0.04786875 | G14: =明细!Q31 -> YS145
A15: =明细!B32 -> SCREWS | B15: =明细!C32 -> 螺钉 | C15: =明细!L32 -> 1 | D15: =明细!E32 -> 14.5 | E15: =明细!F32 -> 13.5 | F15: =明细!N32 -> 0.014616 | G15: =明细!Q32 -> YS161
A16: =明细!B33 -> Railing bracket | B16: =明细!C33 -> 栏杆支架 | C16: =明细!L33 -> 3 | D16: =明细!E33 -> 17.31 | E16: =明细!F33 -> 14.31 | F16: =明细!N33 -> 0.014322 | G16: =明细!Q33 -> YS382
A17: =明细!B34 -> Railing bracket | B17: =明细!C34 -> 栏杆支架 | C17: =明细!L34 -> 1 | D17: =明细!E34 -> 12.7 | E17: =明细!F34 -> 11.7 | F17: =明细!N34 -> 0.019227 | G17: =明细!Q34 -> YS125
A18: =明细!B35 -> Railing bracket | B18: =明细!C35 -> 栏杆支架 | C18: =明细!L35 -> 1 | D18: =明细!E35 -> 12.25 | E18: =明细!F35 -> 11.25 | F18: =明细!N35 -> 0.019227 | G18: =明细!Q35 -> YS124
A19: =明细!B36 -> Railing bracket | B19: =明细!C36 -> 栏杆支架 | C19: =明细!L36 -> 4 | D19: =明细!E36 -> 15.44 | E19: =明细!F36 -> 11.44 | F19: =明细!N36 -> 0.013608 | G19: =明细!Q36 -> YS381
A20: =明细!B37 -> SCREWS | B20: =明细!C37 -> 螺钉 | C20: =明细!L37 -> 2 | D20: =明细!E37 -> 29.6 | E20: =明细!F37 -> 27.6 | F20: =明细!N37 -> 0.07106 | G20: =明细!Q37 -> YS356
... A58: =明细!B75 -> SCREWS | B58: =明细!C75 -> 螺钉 | C58: =明细!L75 -> 6 | D58: =明细!E75 -> 99 | E58: =明细!F75 -> 93 | F58: =明细!N75 -> 0.102144 | G58: =明细!Q75 -> YS50
A59: =明细!B76 -> 0
A60: TOTAL: | C60: =SUM(C9:C59) -> 270 | D60: =SUM(D9:D59) -> 2228.76 | E60: =SUM(E9:E59) -> 1958.76 | F60: =SUM(F9:F59) -> 3.892832

Sheet 报关单
A1: 中华人民共和国海关出口货物报关单
A2: 预录入编号： 海关编号： 页码/页数：
A3: 境内发货人 | B3: =明细!G4 -> 91310120MABY7LT67T | D3: 出境关别 | G3: 出口日期 | I3: 申报日期 | J3: 备案号
A4: =明细!G2 -> 上海福洺电子商务有限公司
A5: 境外收货人 | D5: 运输方式 | G5: 运输工具名称及航次号 | I5: 提运单号
A6: =明细!A7 -> Amazon.com Services, Inc. | D6: =明细!G11 -> BY SEA
A7: 生产销售单位 | B7: =B3 -> 91310120MABY7LT67T | D7: 监管方式 | G7: 征免性质 | I7: 许可证号
A8: =A4 -> 上海福洺电子商务有限公司 | D8: 一般贸易
A9: 合同协议号 | D9: 贸易国（地区） | G9: 运抵国（地区） | I9: 指运港 | J9: 离境口岸
A10: =明细!G9 -> HY26011821-1 | D10: =明细!G14 -> 美国 | G10: =明细!G15 -> 美国 | I10: =明细!G16 -> 0
A11: 包装种类 | D11: 件数 | E11: 毛重（千克） | G11: 净重(千克) | H11: 成交方式 | I11: 运费 | J11: 保费 | K11: 杂费
A12: 纸箱 | D12: =明细!L76 -> 270 | E12: =明细!E76 -> 2228.76 | G12: =明细!F76 -> 1958.76 | H12: =明细!G17 -> FOB | I12: =明细!G19 -> 0
A13: 随附单证及编号 随附单证1：随附单证2：
A14: 标记唛码及备注
A16: 项号 | B16: 商品编号 | C16: 商品名称及规格型号 | E16: 数量及单位 | G16: 单价/总价/币制 | H16: 原产国(地区) | I16: 最终目的国（地区） | J16: 境内货源地 | K16: 征免
A17: =明细!A26 -> 1 | B17: =明细!D26 -> 7318159090 | C17: =明细!C26 -> 螺钉 | E17: =明细!I26 -> 16 | F17: =明细!J26 -> 套 | G17: =明细!G26 -> 6.22 | H17: 中国 | I17: =明细!G14 -> 美国 | J17: =明细!P26 -> 上海奉贤 | K17: 一般征免 | L17: =明细!Q26 -> YS323
G18: =明细!H26 -> 99.52 | H18: (CHN)
G19: =明细!H21 -> 美元
A20: =明细!A27 -> 2 | B20: =明细!D27 -> 7318159090 | C20: =明细!C27 -> 螺钉 | E20: =明细!I27 -> 12 | F20: =明细!J27 -> 套 | G20: =明细!G27 -> 9.38 | H20: 中国 | I20: =明细!G14 -> 美国 | J20: =明细!P27 -> 上海奉贤 | K20: 一般征免 | L20: =明细!Q27 -> YS325
G21: =明细!H27 -> 112.56 | H21: (CHN)
G22: =明细!H21 -> 美元
A23: =明细!A28 -> 3 | B23: =明细!D28 -> 7318159090 | C23: =明细!C28 -> 螺钉 | E23: =明细!I28 -> 12 | F23: =明细!J28 -> 套 | G23: =明细!G28 -> 10.68 | H23: 中国 | I23: =明细!G14 -> 美国 | J23: =明细!P28 -> 上海奉贤 | K23: 一般征免 | L23: =明细!Q28 -> YS327
G24: =明细!H28 -> 128.16 | H24: (CHN)
G25: =明细!H21 -> 美元
A26: =明细!A29 -> 4 | B26: =明细!D29 -> 7318159090 | C26: =明细!C29 -> 螺钉 | E26: =明细!I29 -> 36 | F26: =明细!J29 -> 套 | G26: =明细!G29 -> 3.49 | H26: 中国 | I26: =明细!G14 -> 美国 | J26: =明细!P29 -> 上海奉贤 | K26: 一般征免 | L26: =明细!Q29 -> YS328
G27: =明细!H29 -> 125.64 | H27: (CHN)
G28: =明细!H21 -> 美元
A29: =明细!A30 -> 5 | B29: =明细!D30 -> 7318159090 | C29: =明细!C30 -> 螺钉 | E29: =明细!I30 -> 36 | F29: =明细!J30 -> 套 | G29: =明细!G30 -> 7.52 | H29: 中国 | I29: =明细!G14 -> 美国 | J29: =明细!P30 -> 上海奉贤 | K29: 一般征免 | L29: =明细!Q30 -> YS329
G30: =明细!H30 -> 270.72 | H30: (CHN)
G31: =明细!H21 -> 美元
A32: =明细!A31 -> 6 | B32: =明细!D31 -> 7318159090 | C32: =明细!C31 -> 螺钉 | E32: =明细!I31 -> 8 | F32: =明细!J31 -> 套 | G32: =明细!G31 -> 13.74 | H32: 中国 | I32: =明细!G14 -> 美国 | J32: =明细!P31 -> 上海奉贤 | K32: 一般征免 | L32: =明细!Q31 -> YS145
G33: =明细!H31 -> 109.92 | H33: (CHN)
G34: =明细!H21 -> 美元
A35: =明细!A32 -> 7 | B35: =明细!D32 -> 7318159090 | C35: =明细!C32 -> 螺钉 | E35: =明细!I32 -> 12 | F35: =明细!J32 -> 套 | G35: =明细!G32 -> 7.99 | H35: 中国 | I35: =明细!G14 -> 美国 | J35: =明细!P32 -> 上海奉贤 | K35: 一般征免 | L35: =明细!Q32 -> YS161
G36: =明细!H32 -> 95.88 | H36: (CHN)
G37: =明细!H21 -> 美元
A38: =明细!A33 -> 8 | B38: =明细!D33 -> 7326909000 | C38: =明细!C33 -> 栏杆支架 | E38: =明细!I33 -> 3 | F38: =明细!J33 -> 套 | G38: =明细!G33 -> 30.09 | H38: 中国 | I38: =明细!G14 -> 美国 | J38: =明细!P33 -> 江苏盐城 | K38: 一般征免 | L38: =明细!Q33 -> YS382
G39: =明细!H33 -> 90.27 | H39: (CHN)
G40: =明细!H21 -> 美元
A41: =明细!A34 -> 9 | B41: =明细!D34 -> 7326909000 | C41: =明细!C34 -> 栏杆支架 | E41: =明细!I34 -> 12 | F41: =明细!J34 -> 套 | G41: =明细!G34 -> 5.01 | H41: 中国 | I41: =明细!G14 -> 美国 | J41: =明细!P34 -> 江苏盐城 | K41: 一般征免 | L41: =明细!Q34 -> YS125
...

Sheet 申报要素
A1: 申报要素
A2: =明细!O26 -> 0|0|不锈钢|460-750MPA|无品牌|无型号|4.85MM
A3: =明细!O27 -> 0|0|不锈钢|460-750MPA|无品牌|无型号|4.85MM
A4: =明细!O28 -> 0|0|不锈钢|460-750MPA|无品牌|无型号|4.85MM
A5: =明细!O29 -> 0|0|不锈钢|460-750MPA|无品牌|无型号|4.85MM
A6: =明细!O30 -> 0|0|不锈钢|460-750MPA|无品牌|无型号|4.85MM
A7: =明细!O31 -> 0|0|不锈钢|460-750MPA|无品牌|无型号|4.85MM
A8: =明细!O32 -> 0|0|不锈钢|460-750MPA|无品牌|无型号|4.85MM
A9: =明细!O33 -> 0|0|非工业用|铁|锻造
A10: =明细!O34 -> 0|0|非工业用|铁|锻造
A11: =明细!O35 -> 0|0|非工业用|铁|锻造
A12: =明细!O36 -> 0|0|非工业用|铁|锻造
A13: =明细!O37 -> 0|0|铁|460-750MPA|无品牌|无型号|4.85MM
... A51: =明细!O75 -> 0|0|铁|460-750MPA|无品牌|无型号|4.85MM
